Workbook
Name Customer: #REF!
Name RFQType: #REF!
Name TEAM: #REF!

Sheet FAK-SCHEDULE
B1: TYPE | C1: USER | D1: ACCOUNT | E1: OWNER | G1: VALIDITY & FREQUENCY | N1: ORIGIN/DESINATION VALIDITY | R1: OFR SURCHARGES VALIDITY | AA1: UPDATES | AC1: 46132
B2: REGIONAL/ GLOBAL | C2: RFQ HANDLER | D2: WWA CUSTOMER | E2: GLOBAL/REGIONAL ACCOUNT OWNER | F2: RFQ OWNER | G2: FREQUENCY (FOB/PLC) | H2: FREQUENCY (OFR) | I2: FREQUENCY (OFR SURCHARGES) | J2: FOB/PLC VALIDITY EFFECTIVE DATE | K2: FOB/PLC VALIDITY EXPIRY DATE | L2: OFR VALIDITY EFFECTIVE DATE | M2: OFR VALIDITY EXPIRY DATE | N2: ORIGIN E-INF SURCHARGE | O2: DESTINATION E-INF SURCHARGE | P2: MPCI FILING FEE | Q2: DMCE FILING FEE | R2: IMO2020 SURCHARGES | S2: GRI SURCHARGES | T2: ETSS/FEMS SURCHARGES | U2: ESF SURCHARGES | V2: E-PSS SURCHARGES | W2: LWS/PCS SURCHARGES | X2: E-BAF SURCHARGES | Y2: WRS SURCHARGES | Z2: REMARKS | AA2: FOB/PLC FOLLOW-UP | AB2: OFR FOLLOW-UP
A3: =VLOOKUP(D3,'[1]WWA Timelines '!$A:$A,1,0) -> AIT (RA) | B3: REGIONAL | C3: Sunil | D3: AIT (RA) | E3: KEVIN TAYLOR | F3: HELEN LI | G3: YEARLY | H3: YEARLY | I3: BI-WEEKLY (1-15: Member; 16-31: Advisory) | J3: 46143 | K3: 46387 | L3: 46143 | M3: 46387 | R3: MONTHLY (MEMBERS) | S3: MONTHLY (MEMBERS) | T3: MONTHLY (MEMBERS) | U3: BI-WEEKLY (MEMBERS/ADVISORY) | V3: BI-WEEKLY (MEMBERS/ADVISORY) | W3: BI-WEEKLY (MEMBERS/ADVISORY) | X3: BI-WEEKLY (MEMBERS/ADVISORY) | Y3: BI-WEEKLY (ADVISORY) | AA3: =IFERROR(NETWORKDAYS(K3,$AC$1),"-") -> -184 | AB3: =IFERROR(NETWORKDAYS(M3,$AC$1),"-") -> -184
A4: =VLOOKUP(D4,'[1]WWA Timelines '!$A:$A,1,0) -> APL LOGISTICS | B4: GLOBAL | C4: Sonali | D4: APL LOGISTICS | E4: MICHELLE YU | F4: IRTASIA | G4: QUARTERLY | H4: QUARTERLY | I4: BI-WEEKLY (MEMBERS) | J4: 46204 | K4: 46295 | L4: 46204 | M4: 46295 | N4: BI-WEEKLY (ADVISORY) | O4: BI-WEEKLY (ADVISORY) | R4: QUARTERLY | S4: BI-WEEKLY (MEMBERS) | T4: QUARTERLY | U4: BI-WEEKLY (MEMBERS) | V4: BI-WEEKLY (MEMBERS) | W4: BI-WEEKLY (MEMBERS) | X4: BI-WEEKLY (MEMBERS) | Y4: BI-WEEKLY (ADVISORY) | AA4: =IFERROR(NETWORKDAYS(K4,$AC$1),"-") -> -118 | AB4: =IFERROR(NETWORKDAYS(M4,$AC$1),"-") -> -118
A5: =VLOOKUP(D5,'[1]WWA Timelines '!$A:$A,1,0) -> ARAMEX (RA) | B5: REGIONAL | C5: Rohan | D5: ARAMEX (RA) | E5: ELVIRA TAKX / MARY ANNE CHUA | F5: IRTASIA | G5: YEARLY | H5: MONTHLY | I5: BI-WEEKLY (1-15: Member; 16-31: Advisory) | J5: 46023 | K5: 46387 | L5: 46174 | M5: 46203 | R5: MONTHLY (MEMBERS) | S5: MONTHLY (MEMBERS) | T5: MONTHLY (MEMBERS) | U5: BI-WEEKLY (MEMBERS/ADVISORY) | V5: BI-WEEKLY (MEMBERS/ADVISORY) | W5: BI-WEEKLY (MEMBERS/ADVISORY) | X5: BI-WEEKLY (MEMBERS/ADVISORY) | Y5: BI-WEEKLY (ADVISORY) | Z5: 1st Half - Members involvement 2nd Half - As per Advisory | AA5: =IFERROR(NETWORKDAYS(K5,$AC$1),"-") -> -184 | AB5: =IFERROR(NETWORKDAYS(M5,$AC$1),"-") -> -52
A6: =VLOOKUP(D6,'[1]WWA Timelines '!$A:$A,1,0) -> BARSAN (RA) | B6: REGIONAL | C6: Rohan | D6: BARSAN (RA) | E6: RYAN ROBERT HOWELL | F6: HELEN LI | G6: YEARLY | H6: MONTHLY | I6: BI-WEEKLY (1-15: Member; 16-31: Advisory) | J6: 46023 | K6: 46387 | L6: 46174 | M6: 46203 | R6: MONTHLY (MEMBERS) | S6: MONTHLY (MEMBERS) | T6: MONTHLY (MEMBERS) | U6: BI-WEEKLY (MEMBERS/ADVISORY) | V6: BI-WEEKLY (MEMBERS/ADVISORY) | W6: BI-WEEKLY (MEMBERS/ADVISORY) | X6: BI-WEEKLY (MEMBERS/ADVISORY) | Y6: EXCL. AS PER ADVISORY | Z6: 1st Half - Members involvement 2nd Half - As per Advisory | AA6: =IFERROR(NETWORKDAYS(K6,$AC$1),"-") -> -184 | AB6: =IFERROR(NETWORKDAYS(M6,$AC$1),"-") -> -52
A7: =VLOOKUP(D7,'[1]WWA Timelines '!$A:$A,1,0) -> CARGO PARTNER | B7: GLOBAL | C7: Sunil | D7: CARGO PARTNER | E7: MARTIN SCHULZ | F7: DENNIS FRANKOWSKI | G7: YEARLY | H7: MONTHLY | I7: BI-WEEKLY (1-15: Member; 16-31: Advisory) | J7: 46023 | K7: 46387 | L7: 46174 | M7: 46203 | N7: BI-WEEKLY (ADVISORY) | O7: BI-WEEKLY (ADVISORY) | R7: MONTHLY (MEMBERS) | S7: MONTHLY (MEMBERS) | T7: MONTHLY (MEMBERS) | U7: BI-WEEKLY (MEMBERS/ADVISORY) | V7: BI-WEEKLY (MEMBERS/ADVISORY) | W7: BI-WEEKLY (MEMBERS/ADVISORY) | X7: BI-WEEKLY (MEMBERS/ADVISORY) | Y7: BI-WEEKLY (ADVISORY) | Z7: 1st Half - Members involvement 2nd Half - As per Advisory | AA7: =IFERROR(NETWORKDAYS(K7,$AC$1),"-") -> -184 | AB7: =IFERROR(NETWORKDAYS(M7,$AC$1),"-") -> -52
A8: =VLOOKUP(D8,'[1]WWA Timelines '!$A:$A,1,0) -> CEVA | B8: GLOBAL | C8: Kajal | D8: CEVA | E8: JAKOB BLUHME | F8: SANTIAGO | G8: YEARLY | H8: YEARLY | I8: BI-WEEKLY (MEMBERS) | J8: 46023 | K8: 46387 | L8: 46082 | M8: 46387 | N8: BI-WEEKLY (ADVISORY) | O8: BI-WEEKLY (ADVISORY) | R8: MONTHLY (MEMBERS) | S8: MONTHLY (MEMBERS) | T8: MONTHLY (MEMBERS) | U8: BI-WEEKLY (MEMBERS) | V8: BI-WEEKLY (MEMBERS) | W8: BI-WEEKLY (MEMBERS) | X8: BI-WEEKLY (ADVISORY) | Y8: BI-WEEKLY (ADVISORY) | Z8: IMO2020/GRI/ESF/E-PSS/LWS/PCS UNDER RATE ADJUSTMENT COLUMN | AA8: =IFERROR(NETWORKDAYS(K8,$AC$1),"-") -> -184 | AB8: =IFERROR(NETWORKDAYS(M8,$AC$1),"-") -> -184
A9: =VLOOKUP(D9,'[1]WWA Timelines '!$A:$A,1,0) -> CH ROBINSON | B9: GLOBAL | C9: Sonali | D9: CH ROBINSON | E9: BRUCE ERICSON | F9: HELEN LI | G9: 6 MONTHS | H9: BI-WEEKLY | I9: BI-WEEKLY (MEMBERS) | J9: 46188 | K9: 46401 | L9: 46188 | M9: 46217 | N9: BI-WEEKLY (AGREEMENT) | O9: BI-WEEKLY (AGREEMENT) | R9: BI-WEEKLY (MEMBERS) | S9: BI-WEEKLY (MEMBERS) | T9: QUARTERLY | U9: BI-WEEKLY (MEMBERS) | V9: BI-WEEKLY (MEMBERS) | W9: BI-WEEKLY (MEMBERS) | X9: BI-WEEKLY (ADVISORY) | Y9: EXCL. AS PER ADVISORY | AA9: =IFERROR(NETWORKDAYS(K9,$AC$1),"-") -> -194 | AB9: =IFERROR(NETWORKDAYS(M9,$AC$1),"-") -> -62
A10: =VLOOKUP(D10,'[1]WWA Timelines '!$A:$A,1,0) -> CRANE WORLDWIDE | B10: GLOBAL | C10: Aseem | D10: CRANE WORLDWIDE | E10: METTE KARAPETIAN | F10: CHRIS CROWDER / HELEN LI | G10: MONTHLY | H10: MONTHLY | I10: BI-WEEKLY (1-15: Member; 16-31: Advisory) | J10: 46204 | K10: 46234 | L10: 46174 | M10: 46203 | N10: BI-WEEKLY (ADVISORY) | O10: BI-WEEKLY (ADVISORY) | R10: MONTHLY (MEMBERS) | S10: MONTHLY (MEMBERS) | T10: MONTHLY (MEMBERS) | U10: BI-WEEKLY (MEMBERS/ADVISORY) | V10: BI-WEEKLY (MEMBERS/ADVISORY) | W10: BI-WEEKLY (MEMBERS/ADVISORY) | X10: BI-WEEKLY (MEMBERS/ADVISORY) | Y10: BI-WEEKLY (ADVISORY) | Z10: 1st Half - Members involvement 2nd Half - As per Advisory | AA10: =IFERROR(NETWORKDAYS(K10,$AC$1),"-") -> -75 | AB10: =IFERROR(NETWORKDAYS(M10,$AC$1),"-") -> -52
A11: =VLOOKUP(D11,'[1]WWA Timelines '!$A:$A,1,0) -> DACHSER (EXCL. INTRA ASIA) | B11: GLOBAL | C11: Sachin | D11: DACHSER (EXCL. INTRA ASIA) | E11: MARTIN SCHULZ | F11: NADINE | G11: YEARLY | H11: MONTHLY | I11: BI-WEEKLY (1-15: Member; 16-31: Advisory) | J11: 46023 | K11: 46387 | L11: 46174 | M11: 46203 | R11: MONTHLY (MEMBERS) | S11: MONTHLY (MEMBERS) | T11: QUARTERLY (MEMBERS) | U11: BI-WEEKLY (MEMBERS/ADVISORY) | V11: BI-WEEKLY (MEMBERS/ADVISORY) | W11: BI-WEEKLY (MEMBERS/ADVISORY) | X11: BI-WEEKLY (MEMBERS/ADVISORY) | Y11: BI-WEEKLY (ADVISORY) | Z11: 1st Half - Members involvement 2nd Half - As per Advisory | AA11: =IFERROR(NETWORKDAYS(K11,$AC$1),"-") -> -184 | AB11: =IFERROR(NETWORKDAYS(M11,$AC$1),"-") -> -52
A12: =VLOOKUP(D12,'[1]WWA Timelines '!$A:$A,1,0) -> #N/A | B12: GLOBAL | C12: Sachin | D12: DACHSER (AU/NZ) | E12: JENS POTTSCHUL | F12: IRTASIA/MARIA GIRLIE | G12: YEARLY | H12: QUARTERLY | I12: - | J12: 45809 | K12: 46203 | L12: 46082 | M12: 46203 | R12: QUARTERLY | S12: QUARTERLY | T12: NA | U12: INCL. IN OFR | V12: INCL. IN OFR | W12: INCL. IN OFR | X12: EXCL. AS PER ADVISORY | Y12: EXCL. AS PER ADVISORY | Z12: SAME AS OFR VALIDITY | AA12: =IFERROR(NETWORKDAYS(K12,$AC$1),"-") -> -52 | AB12: =IFERROR(NETWORKDAYS(M12,$AC$1),"-") -> -52
A13: =VLOOKUP(D13,'[1]WWA Timelines '!$A:$A,1,0) -> DACHSER INTRA ASIA | B13: GLOBAL | C13: Sachin | D13: DACHSER INTRA ASIA | E13: JENS POTTSCHUL | F13: IRTASIA/MARIA GIRLIE | G13: YEARLY | H13: YEARLY | I13: - | J13: 45809 | K13: 46203 | L13: 45809 | M13: 46203 | R13: YEARLY | S13: YEARLY | T13: NA | U13: INCL. IN OFR | V13: INCL. IN OFR | W13: INCL. IN OFR | X13: BI-WEEKLY (ADVISORY) | Y13: EXCL. AS PER ADVISORY | Z13: SAME AS OFR VALIDITY | AA13: =IFERROR(NETWORKDAYS(K13,$AC$1),"-") -> -52 | AB13: =IFERROR(NETWORKDAYS(M13,$AC$1),"-") -> -52
A14: =VLOOKUP(D14,'[1]WWA Timelines '!$A:$A,1,0) -> DHL | B14: GLOBAL | C14: Kajal | D14: DHL | E14: JAKOB BLUHME | F14: SANTIAGO | G14: YEARLY | H14: YEARLY | I14: QUARTERLY (MEMBERS) | J14: 46023 | K14: 46387 | L14: 46113 | M14: 46387 | N14: BI-WEEKLY (AGREEMENT) | O14: BI-WEEKLY (AGREEMENT) | R14: YEARLY | S14: YEARLY | T14: YEARLY | U14: QUARTERLY (MEMBERS) | V14: QUARTERLY (MEMBERS) | W14: QUARTERLY (MEMBERS) | X14: All US Origins to All Destinations Worldwide USD 6.00 w/m, INTRA ASIA USD 3.00 w/m, All other trade lanes WW USD 7.00 w/m. | Y14: EXCL. AS PER ADVISORY | Z14: UNDER ECRS (ESF,E-PSS,LWS/PCS) | AA14: =IFERROR(NETWORKDAYS(K14,$AC$1),"-") -> -184 | AB14: =IFERROR(NETWORKDAYS(M14,$AC$1),"-") -> -184
A15: =VLOOKUP(D15,'[1]WWA Timelines '!$A:$A,1,0) -> DP WORLD | B15: GLOBAL | C15: Aseem | D15: DP WORLD | E15: MARTIN SCHULZ | F15: NADINE/SANTIAGO | G15: YEARLY | H15: MONTHLY | I15: BI-WEEKLY (1-15: Member; 16-31: Advisory) | J15: 46023 | K15: 46387 | L15: 46174 | M15: 46203 | N15: BI-WEEKLY (ADVISORY) | O15: BI-WEEKLY (ADVISORY) | R15: MONTHLY (MEMBERS) | S15: MONTHLY (MEMBERS) | T15: MONTHLY (MEMBERS) | U15: BI-WEEKLY (MEMBERS/ADVISORY) | V15: BI-WEEKLY (MEMBERS/ADVISORY) | W15: BI-WEEKLY (MEMBERS/ADVISORY) | X15: BI-WEEKLY (MEMBERS/ADVISORY) | Y15: BI-WEEKLY (ADVISORY) | AA15: =IFERROR(NETWORKDAYS(K15,$AC$1),"-") -> -184 | AB15: =IFERROR(NETWORKDAYS(M15,$AC$1),"-") -> -52
A16: =VLOOKUP(D16,'[1]WWA Timelines '!$A:$A,1,0) -> DSV GLOBAL (RFQ & NON-RFQ LANES) | B16: GLOBAL | C16: Aseem | D16: DSV GLOBAL (RFQ & NON-RFQ LANES) | E16: JAKOB BLUHME | F16: SANTIAGO | G16: YEARLY | H16: YEARLY | I16: MONTHLY (MEMBERS) | J16: 46113 | K16: 46477 | L16: 46113 | M16: 46477 | N16: BI-WEEKLY (ADVISORY) | O16: BI-WEEKLY (ADVISORY) | R16: MONTHLY (MEMBERS) | S16: MONTHLY (MEMBERS) | T16: MONTHLY (MEMBERS) | U16: MONTHLY (MEMBERS) | V16: MONTHLY (MEMBERS) | W16: MONTHLY (MEMBERS) | X16: MONTHLY (MEMBERS) | Y16: MONTHLY (AS PER ANNOUNCEMENT) | Z16: IMO2020/GRI/ETSS/FEMS/ESF/E-PSS/LWS/PCS UNDER RATE ADJUSTMENT COLUMN | AA16: =IFERROR(NETWORKDAYS(K16,$AC$1),"-") -> -248 | AB16: =IFERROR(NETWORKDAYS(M16,$AC$1),"-") -> -248
A17: =VLOOKUP(D17,'[1]WWA Timelines '!$A:$A,1,0) -> #N/A | B17: GLOBAL | C17: Rohan | D17: EFL | E17: HELEN LI | F17: - | G17: YEARLY | H17: MONTHLY | I17: BI-WEEKLY (ADVISORY) | J17: 46189 | K17: 46387 | L17: 46189 | M17: 46203 | N17: BI-WEEKLY (ADVISORY) | O17: BI-WEEKLY (ADVISORY) | R17: MONTHLY (MEMBERS) | S17: MONTHLY (MEMBERS) | T17: MONTHLY (MEMBERS) | U17: BI-WEEKLY (ADVISORY) | V17: BI-WEEKLY (ADVISORY) | W17: BI-WEEKLY (ADVISORY) | X17: BI-WEEKLY (ADVISORY) | Y17: BI-WEEKLY (ADVISORY) | AA17: =IFERROR(NETWORKDAYS(K17,$AC$1),"-") -> -184 | AB17: =IFERROR(NETWORKDAYS(M17,$AC$1),"-") -> -52
A18: =VLOOKUP(D18,'[1]WWA Timelines '!$A:$A,1,0) -> EV CARGO (RA) | B18: REGIONAL | C18: Sachin | D18: EV CARGO (RA) | E18: MARY-ANNE CHUA/CHRISTINE ZHENG | F18: IRTASIA | G18: YEARLY | H18: QUARTERLY | I18: BI-WEEKLY (ADVISORY) | J18: 46023 | K18: 46387 | L18: 46204 | M18: 46295 | N18: BI-WEEKLY (ADVISORY) | O18: BI-WEEKLY (ADVISORY) | R18: QUARTERLY | S18: QUARTERLY | T18: QUARTERLY | U18: BI-WEEKLY (ADVISORY) | V18: BI-WEEKLY (ADVISORY) | W18: BI-WEEKLY (ADVISORY) | X18: BI-WEEKLY (ADVISORY) | Y18: BI-WEEKLY (ADVISORY) | AA18: =IFERROR(NETWORKDAYS(K18,$AC$1),"-") -> -184 | AB18: =IFERROR(NETWORKDAYS(M18,$AC$1),"-") -> -118
A19: =VLOOKUP(D19,'[1]WWA Timelines '!$A:$A,1,0) -> EXPEDITORS | B19: GLOBAL | C19: Sachin | D19: EXPEDITORS | E19: METTE KARAPETIAN/SYLVIA LATHOUWERS | F19: - | G19: 6 MONTHS | H19: MONTHLY | I19: BI-WEEKLY (1-15: Member; 16-31: Advisory) | J19: 46204 | K19: 46387 | L19: 46174 | M19: 46203 | N19: BI-WEEKLY (ADVISORY) | O19: BI-WEEKLY (ADVISORY) | P19: PRE-DEFINED (AGREEMENT) | R19: MONTHLY (MEMBERS) | S19: MONTHLY (MEMBERS) | T19: MONTHLY (MEMBERS) | U19: BI-WEEKLY (MEMBERS/ADVISORY) | V19: BI-WEEKLY (MEMBERS/ADVISORY) | W19: MONTHLY (MEMBERS) | X19: BI-WEEKLY (ADVISORY) | Y19: BI-WEEKLY (ADVISORY) | Z19: 1st Half - Members involvement 2nd Half - As per Advisory | AA19: =IFERROR(NETWORKDAYS(K19,$AC$1),"-") -> -184 | AB19: =IFERROR(NETWORKDAYS(M19,$AC$1),"-") -> -52
A20: =VLOOKUP(D20,'[1]WWA Timelines '!$A:$A,1,0) -> FEDEXTRADE | B20: GLOBAL | C20: Sonali | D20: FEDEXTRADE | E20: METTE KARAPETIAN/SANTIAGO MILIAN | F20: HELEN | G20: YEARLY | H20: MONTHLY | I20: BI-WEEKLY (1-15: Member; 16-31: Advisory) | J20: 46023 | K20: 46387 | L20: 46174 | M20: 46203 | R20: MONTHLY (MEMBERS) | S20: MONTHLY (MEMBERS) | T20: MONTHLY (MEMBERS) | U20: BI-WEEKLY (MEMBERS/ADVISORY) | V20: BI-WEEKLY (MEMBERS/ADVISORY) | W20: MONTHLY (MEMBERS) | X20: MONTHLY (MEMBERS) | Y20: BI-WEEKLY (ADVISORY) | Z20: 1st Half - Members involvement 2nd Half - As per Advisory | AA20: =IFERROR(NETWORKDAYS(K20,$AC$1),"-") -> -184 | AB20: =IFERROR(NETWORKDAYS(M20,$AC$1),"-") -> -52
A21: =VLOOKUP(D21,'[1]WWA Timelines '!$A:$A,1,0) -> FIBS (RA) | B21: REGIONAL | C21: Rohan | D21: FIBS (RA) | E21: MARY-ANNE CHUA/CHRISTINE ZHENG | F21: IRTASIA | G21: YEARLY | H21: QUARTERLY | I21: BI-WEEKLY (ADVISORY) | J21: 46023 | K21: 46387 | L21: 46204 | M21: 46295 | N21: BI-WEEKLY (ADVISORY) | O21: BI-WEEKLY (ADVISORY) | R21: QUARTERLY | S21: QUARTERLY | T21: QUARTERLY | U21: BI-WEEKLY (ADVISORY) | V21: BI-WEEKLY (ADVISORY) | W21: BI-WEEKLY (ADVISORY) | X21: BI-WEEKLY (ADVISORY) | Y21: BI-WEEKLY (ADVISORY) | AA21: =IFERROR(NETWORKDAYS(K21,$AC$1),"-") -> -184 | AB21: =IFERROR(NETWORKDAYS(M21,$AC$1),"-") -> -118
A22: =VLOOKUP(D22,'[1]WWA Timelines '!$A:$A,1,0) -> FIVE STAR (RA) | B22: REGIONAL | C22: Sachin | D22: FIVE STAR (RA) | E22: MARTIN SCHULZ | F22: DENNIS FRANKOWSKI | G22: YEARLY | H22: MONTHLY | I22: BI-WEEKLY (1-15: Member; 16-31: Advisory) | J22: 46023 | K22: 46387 | L22: 46174 | M22: 46203 | N22: BI-WEEKLY (ADVISORY) | O22: BI-WEEKLY (ADVISORY) | P22: PRE-DEFINED (AGREEMENT) | R22: MONTHLY (MEMBERS) | S22: MONTHLY (MEMBERS) | T22: QUARTERLY | U22: BI-WEEKLY (MEMBERS/ADVISORY) | V22: BI-WEEKLY (MEMBERS/ADVISORY) | W22: BI-WEEKLY (MEMBERS/ADVISORY) | X22: BI-WEEKLY (MEMBERS/ADVISORY) | Y22: BI-WEEKLY (ADVISORY) | Z22: 1st Half - Members involvement 2nd Half - As per Advisory | AA22: =IFERROR(NETWORKDAYS(K22,$AC$1),"-") -> -184 | AB22: =IFERROR(NETWORKDAYS(M22,$AC$1),"-") -> -52
A23: =VLOOKUP(D23,'[1]WWA Timelines '!$A:$A,1,0) -> FLEXPORT | B23: GLOBAL | C23: Sachin | D23: FLEXPORT | E23: JENS POTTSCHUL | F23: MICHELLE YU CC. MARIA GIRLIE & IRT ASIA | G23: YEARLY | H23: MONTHLY | I23: BI-WEEKLY (1-15: Member; 16-31: Advisory) | J23: 46023 | K23: 46387 | L23: 46174 | M23: 46203 | N23: BI-WEEKLY (ADVISORY) | O23: BI-WEEKLY (ADVISORY) | R23: MONTHLY (MEMBERS) | S23: MONTHLY (MEMBERS) | T23: QUARTERLY (MEMBERS) | U23: BI-WEEKLY (MEMBERS/ADVISORY) | V23: BI-WEEKLY (MEMBERS/ADVISORY) | W23: BI-WEEKLY (MEMBERS/ADVISORY) | X23: BI-WEEKLY (MEMBERS/ADVISORY) | Y23: BI-WEEKLY (ADVISORY) | Z23: 1st Half - Members involvement 2nd Half - As per Advisory | AA23: =IFERROR(NETWORKDAYS(K23,$AC$1),"-") -> -184 | AB23: =IFERROR(NETWORKDAYS(M23,$AC$1),"-") -> -52
A24: =VLOOKUP(D24,'[1]WWA Timelines '!$A:$A,1,0) -> GEBR. WEISS | B24: GLOBAL | C24: Aseem | D24: GEBR. WEISS | E24: JAKOB BLUHME | F24: SANTIAGO | G24: YEARLY | H24: MONTHLY | I24: BI-WEEKLY (1-15: Member; 16-31: Advisory) | J24: 46023 | K24: 46387 | L24: 46174 | M24: 46203 | N24: BI-WEEKLY (ADVISORY) | O24: BI-WEEKLY (ADVISORY) | R24: MONTHLY (MEMBERS) | S24: MONTHLY (MEMBERS) | T24: MONTHLY (MEMBERS) | U24: BI-WEEKLY (MEMBERS/ADVISORY) | V24: BI-WEEKLY (MEMBERS/ADVISORY) | W24: BI-WEEKLY (MEMBERS/ADVISORY) | X24: BI-WEEKLY (MEMBERS/ADVISORY) | Y24: BI-WEEKLY (ADVISORY) | Z24: 1st Half - Members involvement 2nd Half - As per Advisory | AA24: =IFERROR(NETWORKDAYS(K24,$AC$1),"-") -> -184 | AB24: =IFERROR(NETWORKDAYS(M24,$AC$1),"-") -> -52
A25: =VLOOKUP(D25,'[1]WWA Timelines '!$A:$A,1,0) -> GEODIS | B25: GLOBAL | C25: Shraddha | D25: GEODIS | E25: MARTIN SCHULZ/SUSANNE ELSBORG-JENSEN | F25: SUSANNE | G25: YEARLY | H25: MONTHLY | I25: BI-WEEKLY (1-15: Member; 16-31: Advisory) | J25: 46023 | K25: 46387 | L25: 46174 | M25: 46203 | R25: MONTHLY (MEMBERS) | S25: MONTHLY (MEMBERS) | T25: MONTHLY (MEMBERS) | U25: BI-WEEKLY (MEMBERS/ADVISORY) | V25: BI-WEEKLY (MEMBERS/ADVISORY) | W25: BI-WEEKLY (MEMBERS/ADVISORY) | X25: BI-WEEKLY (MEMBERS/ADVISORY) | Y25: BI-WEEKLY (ADVISORY) | Z25: 1st Half - Members involvement 2nd Half - As per Advisory | AA25: =IFERROR(NETWORKDAYS(K25,$AC$1),"-") -> -184 | AB25: =IFERROR(NETWORKDAYS(M25,$AC$1),"-") -> -52
A26: =VLOOKUP(D26,'[1]WWA Timelines '!$A:$A,1,0) -> HELLMANN | B26: GLOBAL | C26: Shraddha | D26: HELLMANN | E26: MARTIN SCHULZ/NADINE BEER | F26: NADINE | G26: YEARLY | H26: QUARTERLY | I26: BI-WEEKLY (MEMBERS) | J26: 46054 | K26: 46387 | L26: 46143 | M26: 46265 | N26: BI-WEEKLY (ADVISORY) | O26: BI-WEEKLY (ADVISORY) | R26: QUARTERLY | S26: QUARTERLY | T26: QUARTERLY | U26: BI-WEEKLY (MEMBERS) | V26: BI-WEEKLY (MEMBERS) | W26: BI-WEEKLY (MEMBERS) | X26: PRE-DEFINED (AGREEMENT) | Y26: PRE-DEFINED (AGREEMENT) | Z26: Members involvement | AA26: =IFERROR(NETWORKDAYS(K26,$AC$1),"-") -> -184 | AB26: =IFERROR(NETWORKDAYS(M26,$AC$1),"-") -> -96
A27: =VLOOKUP(D27,'[1]WWA Timelines '!$A:$A,1,0) -> HELLMANN INTRA ASIA | B27: GLOBAL | C27: Shraddha | D27: HELLMANN INTRA ASIA | E27: JENS POTTSCHUL | F27: IRTASIA | G27: YEARLY | H27: QUARTERLY | I27: BI-WEEKLY (ADVISORY) | J27: 46023 | K27: 46387 | L27: 46204 | M27: 46295 | R27: QUARTERLY | S27: QUARTERLY | T27: NA | U27: BI-WEEKLY (ADVISORY) | V27: BI-WEEKLY (ADVISORY) | W27: BI-WEEKLY (ADVISORY) | X27: BI-WEEKLY (ADVISORY) | Y27: EXCL. AS PER ADVISORY | AA27: =IFERROR(NETWORKDAYS(K27,$AC$1),"-") -> -184 | AB27: =IFERROR(NETWORKDAYS(M27,$AC$1),"-") -> -118
A28: =VLOOKUP(D28,'[1]WWA Timelines '!$A:$A,1,0) -> JAS OCEAN | B28: GLOBAL | C28: Sonali | D28: JAS OCEAN | E28: CHRIS CROWDER | F28: HELEN | G28: YEARLY | H28: MONTHLY | I28: BI-WEEKLY (1-15: Member; 16-31: Advisory) | J28: 46023 | K28: 46387 | L28: 46174 | M28: 46203 | Q28: YEARLY | R28: MONTHLY (MEMBERS) | S28: MONTHLY (MEMBERS) | T28: MONTHLY (MEMBERS) | U28: BI-WEEKLY (MEMBERS/ADVISORY) | V28: BI-WEEKLY (MEMBERS/ADVISORY) | W28: BI-WEEKLY (MEMBERS/ADVISORY) | X28: BI-WEEKLY (MEMBERS/ADVISORY) | Y28: BI-WEEKLY (ADVISORY) | Z28: 1st Half - Members involvement 2nd Half - As per Advisory DMCE: Rates effective 1st June 2026 | AA28: =IFERROR(NETWORKDAYS(K28,$AC$1),"-") -> -184 | AB28: =IFERROR(NETWORKDAYS(M28,$AC$1),"-") -> -52
A29: =VLOOKUP(D29,'[1]WWA Timelines '!$A:$A,1,0) -> KLN | B29: GLOBAL | C29: Sunil | D29: KLN | E29: JENS POTTSCHUL | F29: IRTASIA | G29: QUARTERLY | H29: MONTHLY | I29: BI-WEEKLY (1-15: Member; 16-31: Advisory) | J29: 46204 | K29: 46295 | L29: 46174 | M29: 46203 | N29: BI-WEEKLY (ADVISORY) | O29: BI-WEEKLY (ADVISORY) | R29: MONTHLY (MEMBERS) | S29: MONTHLY (MEMBERS) | T29: QUARTERLY (MEMBERS) | U29: BI-WEEKLY (MEMBERS/ADVISORY) | V29: BI-WEEKLY (MEMBERS/ADVISORY) | W29: BI-WEEKLY (MEMBERS/ADVISORY) | X29: BI-WEEKLY (MEMBERS/ADVISORY) | Y29: BI-WEEKLY (ADVISORY) | Z29: 1st Half - Members involvement 2nd Half - As per Advisory | AA29: =IFERROR(NETWORKDAYS(K29,$AC$1),"-") -> -118 | AB29: =IFERROR(NETWORKDAYS(M29,$AC$1),"-") -> -52
A30: =VLOOKUP(D30,'[1]WWA Timelines '!$A:$A,1,0) -> KINTETSU | B30: GLOBAL | C30: Sunil | D30: KINTETSU | E30: JENS POTTSCHUL/MICHELLE YU | F30: IRTASIA | G30: 6 MONTHS | H30: MONTHLY | I30: BI-WEEKLY (1-15: Member; 16-31: Advisory) | J30: 46204 | K30: 46387 | L30: 46174 | M30: 46203 | R30: MONTHLY (MEMBERS) | S30: MONTHLY (MEMBERS) | T30: MONTHLY (MEMBERS) | U30: BI-WEEKLY (MEMBERS/ADVISORY) | V30: BI-WEEKLY (MEMBERS/ADVISORY) | W30: BI-WEEKLY (MEMBERS/ADVISORY) | X30: BI-WEEKLY (MEMBERS/ADVISORY) | Y30: BI-WEEKLY (ADVISORY) | Z30: 1st Half - Members involvement 2nd Half - As per Advisory | AA30: =IFERROR(NETWORKDAYS(K30,$AC$1),"-") -> -184 | AB30: =IFERROR(NETWORKDAYS(M30,$AC$1),"-") -> -52
A31: =VLOOKUP(D31,'[1]WWA Timelines '!$A:$A,1,0) -> KUEHNE & NAGEL | B31: GLOBAL | C31: Aseem | D31: KUEHNE & NAGEL | E31: MARTIN SCHULZ/NADINE BEER | F31: NADINE | G31: YEARLY | H31: MONTHLY | I31: MONTHLY (MEMBERS) | J31: 46023 | K31: 46387 | L31: 46174 | M31: 46203 | N31: BI-WEEKLY (ADVISORY) | O31: BI-WEEKLY (ADVISORY) | R31: MONTHLY (MEMBERS) | S31: MONTHLY (MEMBERS) | T31: INCL. IN OFR | U31: MONTHLY (MEMBERS) | V31: MONTHLY (MEMBERS) | W31: MONTHLY (MEMBERS) | X31: MONTHLY (MEMBERS) | Y31: MONTHLY (MEMBERS) | Z31: UNDER EDS | AA31: =IFERROR(NETWORKDAYS(K31,$AC$1),"-") -> -184 | AB31: =IFERROR(NETWORKDAYS(M31,$AC$1),"-") -> -52
A32: =VLOOKUP(D32,'[1]WWA Timelines '!$A:$A,1,0) -> LESCHACO | B32: GLOBAL | C32: Rohan | D32: LESCHACO | E32: MARTIN SCHULZ/NADINE BEER | F32: NADINE | G32: YEARLY | H32: MONTHLY | I32: BI-WEEKLY (1-15: Member; 16-31: Advisory) | J32: 46023 | K32: 46387 | L32: 46174 | M32: 46203 | N32: BI-WEEKLY (ADVISORY) | O32: BI-WEEKLY (ADVISORY) | R32: MONTHLY (MEMBERS) | S32: MONTHLY (MEMBERS) | T32: MONTHLY (MEMBERS) | U32: BI-WEEKLY (MEMBERS/ADVISORY) | V32: BI-WEEKLY (MEMBERS/ADVISORY) | W32: BI-WEEKLY (MEMBERS/ADVISORY) | X32: EXCL. AS PER ADVISORY | Y32: EXCL. AS PER ADVISORY | Z32: 1st Half - Members involvement 2nd Half - As per Advisory | AA32: =IFERROR(NETWORKDAYS(K32,$AC$1),"-") -> -184 | AB32: =IFERROR(NETWORKDAYS(M32,$AC$1),"-") -> -52
A33: =VLOOKUP(D33,'[1]WWA Timelines '!$A:$A,1,0) -> LIGENTIA (RA) | B33: REGIONAL | C33: Rohan | D33: LIGENTIA (RA) | E33: MARY-ANNE CHUA/CHRISTINE ZHENG | F33: IRTASIA | G33: YEARLY | H33: MONTHLY | I33: BI-WEEKLY (1-15: Member; 16-31: Advisory) | J33: 46023 | K33: 46387 | L33: 46174 | M33: 46203 | N33: BI-WEEKLY (ADVISORY) | O33: BI-WEEKLY (ADVISORY) | R33: MONTHLY (MEMBERS) | S33: MONTHLY (MEMBERS) | T33: MONTHLY (MEMBERS) | U33: BI-WEEKLY (MEMBERS/ADVISORY) | V33: BI-WEEKLY (MEMBERS/ADVISORY) | W33: BI-WEEKLY (MEMBERS/ADVISORY) | X33: BI-WEEKLY (MEMBERS/ADVISORY) | Y33: EXCL. AS PER ADVISORY | Z33: 1st Half - Members involvement 2nd Half - As per Advisory | AA33: =IFERROR(NETWORKDAYS(K33,$AC$1),"-") -> -184 | AB33: =IFERROR(NETWORKDAYS(M33,$AC$1),"-") -> -52
A34: =VLOOKUP(D34,'[1]WWA Timelines '!$A:$A,1,0) -> LOGISTEED (RA) | B34: REGIONAL | C34: Sonali | D34: LOGISTEED (RA) | E34: MARY-ANNE CHUA | F34: IRTASIA | G34: YEARLY | H34: MONTHLY | I34: BI-WEEKLY (1-15: Member; 16-31: Advisory) | J34: 46023 | K34: 46387 | L34: 46174 | M34: 46203 | N34: BI-WEEKLY (ADVISORY) | O34: BI-WEEKLY (ADVISORY) | R34: MONTHLY (MEMBERS) | S34: MONTHLY (MEMBERS) | T34: MONTHLY (MEMBERS) | U34: BI-WEEKLY (MEMBERS/ADVISORY) | V34: BI-WEEKLY (MEMBERS/ADVISORY) | W34: BI-WEEKLY (MEMBERS/ADVISORY) | X34: BI-WEEKLY (MEMBERS/ADVISORY) | Y34: BI-WEEKLY (ADVISORY) | Z34: 1st Half - Members involvement 2nd Half - As per Advisory | AA34: =IFERROR(NETWORKDAYS(K34,$AC$1),"-") -> -184 | AB34: =IFERROR(NETWORKDAYS(M34,$AC$1),"-") -> -52
A35: =VLOOKUP(D35,'[1]WWA Timelines '!$A:$A,1,0) -> MAERSK LOGISTICS GLOBAL | B35: GLOBAL | C35: Sonali | D35: MAERSK LOGISTICS GLOBAL | E35: SUSANNE ELSBORG-JENSEN | F35: SANTIAGO | G35: 6 MONTHS | H35: MONTHLY | I35: BI-WEEKLY (1-15: Member; 16-31: Advisory) | J35: 46204 | K35: 46387 | L35: 46174 | M35: 46203 | R35: MONTHLY (MEMBERS) | S35: MONTHLY (MEMBERS) | T35: MONTHLY (MEMBERS) | U35: BI-WEEKLY (MEMBERS/ADVISORY) | V35: BI-WEEKLY (MEMBERS/ADVISORY) | W35: BI-WEEKLY (MEMBERS/ADVISORY) | X35: BI-WEEKLY (MEMBERS/ADVISORY) | Y35: BI-WEEKLY (ADVISORY) | Z35: 1st Half - Members involvement 2nd Half - As per Advisory | AA35: =IFERROR(NETWORKDAYS(K35,$AC$1),"-") -> -184 | AB35: =IFERROR(NETWORKDAYS(M35,$AC$1),"-") -> -52
A36: =VLOOKUP(D36,'[1]WWA Timelines '!$A:$A,1,0) -> MONDIALE VGL (RA) | B36: REGIONAL | C36: Sachin | D36: MONDIALE VGL (RA) | E36: JOHN FORSTER | F36: KERRY HIRST | G36: QUARTERLY | H36: QUARTERLY | I36: BI-WEEKLY (1-15: Member; 16-31: Advisory) | J36: 46204 | K36: 46295 | L36: 46204 | M36: 46295 | N36: BI-WEEKLY (ADVISORY) | O36: BI-WEEKLY (ADVISORY) | R36: MONTHLY (MEMBERS) | S36: MONTHLY (MEMBERS) | T36: INCL. IN OFR | U36: BI-WEEKLY (MEMBERS/ADVISORY) | V36: BI-WEEKLY (MEMBERS/ADVISORY) | W36: BI-WEEKLY (MEMBERS/ADVISORY) | X36: BI-WEEKLY (MEMBERS/ADVISORY) | Y36: EXCL. AS PER ADVISORY | Z36: 1st Half - Members involvement 2nd Half - As per Advisory | AA36: =IFERROR(NETWORKDAYS(K36,$AC$1),"-") -> -118 | AB36: =IFERROR(NETWORKDAYS(M36,$AC$1),"-") -> -118
A37: =VLOOKUP(D37,'[1]WWA Timelines '!$A:$A,1,0) -> MORRISON EXPRESS (RA) | B37: REGIONAL | C37: Rohan | D37: MORRISON EXPRESS (RA) | E37: KEVIN TAYLOR | F37: RONAN TEOH | G37: YEARLY | H37: MONTHLY | I37: BI-WEEKLY (1-15: Member; 16-31: Advisory) | J37: 46023 | K37: 46387 | L37: 46174 | M37: 46203 | N37: BI-WEEKLY (ADVISORY) | O37: BI-WEEKLY (ADVISORY) | R37: MONTHLY (MEMBERS) | S37: MONTHLY (MEMBERS) | T37: MONTHLY (MEMBERS) | U37: BI-WEEKLY (MEMBERS/ADVISORY) | V37: BI-WEEKLY (MEMBERS/ADVISORY) | W37: BI-WEEKLY (MEMBERS/ADVISORY) | X37: BI-WEEKLY (MEMBERS/ADVISORY) | Y37: EXCL. AS PER ADVISORY | Z37: 1st Half - Members involvement 2nd Half - As per Advisory | AA37: =IFERROR(NETWORKDAYS(K37,$AC$1),"-") -> -184 | AB37: =IFERROR(NETWORKDAYS(M37,$AC$1),"-") -> -52
A38: =VLOOKUP(D38,'[1]WWA Timelines '!$A:$A,1,0) -> NIPPON NX | B38: GLOBAL | C38: Sachin | D38: NIPPON NX | E38: JENS POTTSCHUL | F38: IRTASIA | G38: YEARLY | H38: QUARTERLY | I38: BI-WEEKLY (ADVISORY) | J38: 46023 | K38: 46387 | L38: 46204 | M38: 46295 | N38: BI-WEEKLY (ADVISORY) | O38: BI-WEEKLY (ADVISORY) | R38: QUARTERLY | S38: QUARTERLY | T38: QUARTERLY | U38: BI-WEEKLY (ADVISORY) | V38: BI-WEEKLY (ADVISORY) | W38: BI-WEEKLY (ADVISORY) | X38: BI-WEEKLY (ADVISORY) | Y38: BI-WEEKLY (ADVISORY) | AA38: =IFERROR(NETWORKDAYS(K38,$AC$1),"-") -> -184 | AB38: =IFERROR(NETWORKDAYS(M38,$AC$1),"-") -> -118
A39: =VLOOKUP(D39,'[1]WWA Timelines '!$A:$A,1,0) -> NNR | B39: GLOBAL | C39: Krushna | D39: NNR | E39: JENS POTTSCHUL | F39: - | G39: BI-WEEKLY | H39: BI-WEEKLY | I39: BI-WEEKLY (GRDB) | J39: 46189 | K39: 46203 | L39: 46189 | M39: 46203 | R39: GRDB | S39: GRDB | T39: GRDB | U39: BI-WEEKLY (ADVISORY) | V39: BI-WEEKLY (ADVISORY) | W39: BI-WEEKLY (ADVISORY) | AA39: =IFERROR(NETWORKDAYS(K39,$AC$1),"-") -> -52 | AB39: =IFERROR(NETWORKDAYS(M39,$AC$1),"-") -> -52
A40: =VLOOKUP(D40,'[1]WWA Timelines '!$A:$A,1,0) -> NTG AIR & OCEAN | B40: GLOBAL | C40: Krushna | D40: NTG AIR & OCEAN | E40: SUSANNE ELSBORG-JENSEN | F40: SANTIAGO | G40: YEARLY | H40: MONTHLY | I40: BI-WEEKLY (1-15: Member; 16-31: Advisory) | J40: 46174 | K40: 46387 | L40: 46174 | M40: 46203 | N40: BI-WEEKLY (ADVISORY) | O40: BI-WEEKLY (ADVISORY) | R40: MONTHLY (MEMBERS) | S40: MONTHLY (MEMBERS) | T40: MONTHLY (MEMBERS) | U40: BI-WEEKLY (MEMBERS/ADVISORY) | V40: BI-WEEKLY (MEMBERS/ADVISORY) | W40: BI-WEEKLY (MEMBERS/ADVISORY) | X40: BI-WEEKLY (MEMBERS/ADVISORY) | Y40: BI-WEEKLY (ADVISORY) | AA40: =IFERROR(NETWORKDAYS(K40,$AC$1),"-") -> -184 | AB40: =IFERROR(NETWORKDAYS(M40,$AC$1),"-") -> -52
...

Sheet FAK_Mastersheet
A1: 46198 | B1: GENERAL OVERVIEW | M1: OWNER | O1: SURCHARGES UPDATE OVERVIEW | AD1: CONDITIONAL CHARGES AVAILABLE IN RATE CARD | AJ1: GENERAL
A2: WWA CUSTOMER | B2: FREQUENCY (FOB/PLC) | C2: FREQUENCY (OFR) | D2: FREQUENCY (OFR SURCHARGES) | E2: FOB/PLC VALIDITY EFFECTIVE DATE | F2: FOB/PLC VALIDITY EXPIRY DATE | G2: OFR VALIDITY EFFECTIVE DATE | H2: OFR VALIDITY EXPIRY DATE | I2: FOB/PLC FOLLOW-UP | J2: OFR FOLLOW-UP | K2: UPDATE TYPE | L2: HANDLE VIA | M2: GLOBAL/REGIONAL ACCOUNT OWNER | N2: RFQ OWNER | O2: SOLAS | P2: FILING | Q2: MANDATORY ICS2 ADMIN FEE | R2: CONDITIONAL ICS2 FILING FEE | S2: ORIGIN E-INF | T2: DESTINATION E-INF | U2: MPCI FILING FEE | V2: IMO2020 | W2: GRI | X2: ETSS_FEMS | Y2: ESF | Z2: E-PSS | AA2: LWS_PCS | AB2: E-BAF | AC2: WRS | AD2: HAZ | AE2: 3RD PARTY CFS | AF2: NON-STACKABLE | AG2: STORAGE FREE DAYS | AH2: STORAGE CHARGES | AI2: BMSB | AJ2: Commodity | AK2: Cargo Ratio | AL2: Currency (FOB-PLC) | AM2: Currency (OFR) | AN2: ALTERNATIVE CFS | AO2: NEGATIVE RATES ACCEPTED (Y/N) | AP2: APPROVAL NEEDED FOR OFF CYCLE UPDATE | AQ2: SUBMISSION BEFORE EFFECTIVE DATE | AR2: DIRECT SHARING WITH MEMBERS (Y/N) | AS2: (NON) CENTRALIZED | AT2: OWNER COMMENTS (IF ANY)
A3: AIT (RA) | B3: Yearly | C3: Yearly | D3: Bi-Weekly | E3: 46143 | F3: 46387 | G3: 46143 | H3: 46387 | I3: =IFERROR(NETWORKDAYS($A$1,Table1[[#This Row],[FOB/PLC VALIDITY EXPIRY DATE ]]),"-") -> 136 | J3: =IFERROR(NETWORKDAYS($A$1,Table1[[#This Row],[OFR VALIDITY EXPIRY DATE ]]),"-") -> 136 | K3: OFR & Service Update Request | L3: RFQ TOOL - https://rfqtool.wwalliance.com | M3: Kevin Taylor | N3: Helen Li | O3: Yearly | P3: Yearly | Q3: Yearly | R3: Yearly | S3: Bi-Weekly | T3: Bi-Weekly | U3: Bi-Weekly | V3: Monthly | W3: Monthly | X3: Monthly | Y3: Bi-Weekly | Z3: Bi-Weekly | AA3: Bi-Weekly | AB3: Bi-Weekly | AC3: Bi-Weekly | AD3: Quote Separately For Class 3,6,8,9 | AE3: Quote Separately | AF3: Excluded | AG3: Quote Separately | AH3: Quote Separately | AI3: Excluded | AJ3: General Cargo FAK, (Non HAZ & HAZ Class 3,6,8,9) | AK3: 1:1000 | AL3: USD | AM3: USD | AN3: Not Allowed | AO3: Yes | AP3: No | AQ3: 3 | AR3: Yes | AS3: Yes | AT3: Regional account
A4: APL LOGISTICS | B4: Quarterly | C4: Quarterly | D4: Bi-Weekly | E4: 46204 | F4: 46295 | G4: 46204 | H4: 46295 | I4: =IFERROR(NETWORKDAYS($A$1,Table1[[#This Row],[FOB/PLC VALIDITY EXPIRY DATE ]]),"-") -> 70 | J4: =IFERROR(NETWORKDAYS($A$1,Table1[[#This Row],[OFR VALIDITY EXPIRY DATE ]]),"-") -> 70 | K4: OFR & Service Update Request | L4: CENTRIC - https://centric.wwalliance.com | M4: Michelly Yu | N4: IRTAsia | O4: Quarterly | P4: Quarterly | Q4: Quarterly | R4: Quarterly | S4: Bi-Weekly | T4: Bi-Weekly | U4: Bi-Weekly | V4: Quarterly | W4: Bi-Weekly | X4: Quarterly | Y4: Bi-Weekly | Z4: Bi-Weekly | AA4: Bi-Weekly | AB4: Bi-Weekly | AC4: Bi-Weekly | AD4: Excluded | AE4: Excluded | AF4: Excluded | AG4: Excluded | AH4: Excluded | AI4: Excluded | AJ4: General Cargo FAK, (Non HAZ) | AK4: 1 cbm = 1000 kgs | AL4: USD | AM4: USD | AN4: Allowed | AO4: No | AP4: Yes | AQ4: 12 | AR4: No | AS4: No | AT4: On an exceptional basis Rate Reductions can be made. But need to inform APLL and get their approval first. Also in general this should happen mainly through the adjustment of the surcharges.
A5: ARAMEX (RA) | B5: Yearly | C5: Monthly | D5: Bi-Weekly | E5: 46023 | F5: 46387 | G5: 46174 | H5: 46203 | I5: =IFERROR(NETWORKDAYS($A$1,Table1[[#This Row],[FOB/PLC VALIDITY EXPIRY DATE ]]),"-") -> 136 | J5: =IFERROR(NETWORKDAYS($A$1,Table1[[#This Row],[OFR VALIDITY EXPIRY DATE ]]),"-") -> 4 | K5: OFR & Service Update Request | L5: RFQ TOOL - https://rfqtool.wwalliance.com | M5: Elvira Takx / Mary Anne Chua | N5: IRTAsia | O5: Yearly | P5: Yearly | Q5: Yearly | R5: Yearly | S5: Bi-Weekly | T5: Bi-Weekly | U5: Bi-Weekly | V5: Monthly | W5: Monthly | X5: Monthly | Y5: Bi-Weekly | Z5: Bi-Weekly | AA5: Bi-Weekly | AB5: Bi-Weekly | AC5: Bi-Weekly | AD5: Excluded | AE5: Quote Separately | AF5: Excluded | AG5: Excluded | AH5: Excluded | AI5: Excluded | AJ5: General Cargo FAK, (Non HAZ) | AK5: 1:1 | AL5: Local Currency | AM5: USD | AN5: Allowed | AO5: No | AP5: Yes | AQ5: 5 | AR5: Yes | AS5: Yes | AT5: Regional Account
A6: BARSAN (RA) | B6: Yearly | C6: Monthly | D6: Bi-Weekly | E6: 46023 | F6: 46387 | G6: 46174 | H6: 46203 | I6: =IFERROR(NETWORKDAYS($A$1,Table1[[#This Row],[FOB/PLC VALIDITY EXPIRY DATE ]]),"-") -> 136 | J6: =IFERROR(NETWORKDAYS($A$1,Table1[[#This Row],[OFR VALIDITY EXPIRY DATE ]]),"-") -> 4 | K6: OFR & Service Update Request | L6: CENTRIC - https://centric.wwalliance.com | M6: Ryan Robert Howell | N6: Helen Li | O6: Yearly | P6: Yearly | Q6: Yearly | R6: Yearly | S6: Bi-Weekly | T6: Bi-Weekly | U6: Bi-Weekly | V6: Monthly | W6: Monthly | X6: Monthly | Y6: Bi-Weekly | Z6: Bi-Weekly | AA6: Bi-Weekly | AB6: Bi-Weekly | AC6: Excl. As Per Advisory | AD6: Excluded | AE6: Excluded | AF6: Excluded | AG6: Excluded | AH6: Excluded | AI6: Excluded | AJ6: General Cargo FAK, (Non HAZ) | AK6: 1:1 | AL6: Local Currency | AM6: USD | AN6: Not Allowed | AO6: Yes | AP6: Yes | AQ6: 3 | AR6: Yes | AS6: Yes | AT6: Regional Account
A7: CARGO PARTNER | B7: Yearly | C7: Monthly | D7: Bi-Weekly | E7: 46023 | F7: 46387 | G7: 46174 | H7: 46203 | I7: =IFERROR(NETWORKDAYS($A$1,Table1[[#This Row],[FOB/PLC VALIDITY EXPIRY DATE ]]),"-") -> 136 | J7: =IFERROR(NETWORKDAYS($A$1,Table1[[#This Row],[OFR VALIDITY EXPIRY DATE ]]),"-") -> 4 | K7: OFR & Service Update Request | L7: RFQ TOOL - https://rfqtool.wwalliance.com | M7: Martin Schulz | N7: Dennis Frankowski | O7: Yearly | P7: Yearly | Q7: Yearly | R7: Yearly | S7: Bi-Weekly | T7: Bi-Weekly | U7: Bi-Weekly | V7: Monthly | W7: Monthly | X7: Monthly | Y7: Bi-Weekly | Z7: Bi-Weekly | AA7: Bi-Weekly | AB7: Bi-Weekly | AC7: Bi-Weekly | AD7: Quote Separately For Class 3,6,8,9 | AE7: Excluded | AF7: Excluded | AG7: Excluded | AH7: Excluded | AI7: Quote Separately | AJ7: General Cargo FAK, (Non HAZ & HAZ Class 3,6,8,9) | AK7: 1:3 | AL7: USD/EUR | AM7: USD/EUR | AN7: Not Allowed | AO7: Yes | AP7: Yes | AQ7: 3 | AR7: Yes | AS7: Yes | AT7: Negative Rates Are Accepted As Long As End To End Rates Remain Positive, As Per March 1St 2026, Ofr Validity Will Become Monthly.
A8: CEVA | B8: Yearly | C8: Yearly | D8: Bi-Weekly | E8: 46023 | F8: 46387 | G8: 46082 | H8: 46387 | I8: =IFERROR(NETWORKDAYS($A$1,Table1[[#This Row],[FOB/PLC VALIDITY EXPIRY DATE ]]),"-") -> 136 | J8: =IFERROR(NETWORKDAYS($A$1,Table1[[#This Row],[OFR VALIDITY EXPIRY DATE ]]),"-") -> 136 | K8: OFR & Service Update Request | L8: CENTRIC - https://centric.wwalliance.com | M8: Jakob Bluhme | N8: Santiago | O8: Yearly | P8: Yearly | Q8: Yearly | R8: Yearly | S8: Bi-Weekly | T8: Bi-Weekly | U8: Bi-Weekly | V8: Monthly | W8: Monthly | X8: Monthly | Y8: Bi-Weekly | Z8: Bi-Weekly | AA8: Bi-Weekly | AB8: Bi-Weekly | AC8: Bi-Weekly | AD8: Quote Separately For Class 3,6,8,9 | AE8: Quote Separately | AF8: Excluded | AG8: Quote Separately | AH8: Quote Separately | AI8: Excluded | AJ8: General Cargo FAK, (Non HAZ & HAZ Class 3,6,8,9) | AK8: 1:1000 | AL8: Local Currency | AM8: USD/EUR | AN8: Not Allowed | AO8: Yes (Except OFR Surcharges) | AP8: Yes | AQ8: 3 | AR8: Yes | AS8: Yes | AT8: No Pre-Defined Eff: 1St Of Jan 2026 E-Inf - Maintained Separately In Bd Sheet, Combined In Rate Card Under "Landslide Surcharges"
A9: CH ROBINSON | B9: 6 Months | C9: Bi-Weekly | D9: Bi-Weekly | E9: 46188 | F9: 46401 | G9: 46188 | H9: 46217 | I9: =IFERROR(NETWORKDAYS($A$1,Table1[[#This Row],[FOB/PLC VALIDITY EXPIRY DATE ]]),"-") -> 146 | J9: =IFERROR(NETWORKDAYS($A$1,Table1[[#This Row],[OFR VALIDITY EXPIRY DATE ]]),"-") -> 14 | K9: OFR & Service Update Request | L9: RFQ TOOL - https://rfqtool.wwalliance.com | M9: Bruce Ericson | N9: Helen Li | O9: 6 Months | P9: 6 Months | Q9: 6 Months | R9: 6 Months | S9: Bi-Weekly | T9: Bi-Weekly | U9: Bi-Weekly | V9: Bi-Weekly | W9: Bi-Weekly | X9: Quarterly | Y9: Bi-Weekly | Z9: Bi-Weekly | AA9: Bi-Weekly | AB9: Bi-Weekly | AC9: Excl. As Per Advisory | AD9: Excluded | AE9: Excluded | AF9: Excluded | AG9: Excluded | AH9: Excluded | AI9: Excluded | AJ9: General Cargo FAK, (Non HAZ) | AK9: 1:1 | AL9: Local Currency | AM9: USD/EUR | AN9: Not Allowed | AO9: No | AP9: Yes-Increase; No-Decrease | AQ9: 6 | AR9: Yes | AS9: Yes | AT9: Demand From Chr Is To Submit 4 Business Days Prior Effective Date. / Customer Request That Pricing Be Adjusted Mid Term If There Are Large Fluctuation In Cost. Need To Notify Customer Of Lanes Changed And Reason. Explanation Provided For The Change Submitted E-Inf: Global Application: Please Apply Usd $3 W/M For All Landside Movements. This Amount Should Be Converted Into Local Currency Charges And Applied To Fob/Plc. United Kingdom Application: Please Apply Usd $5 W/M For Exports & Usd $3 W/M For Imports. These Amounts Should Also Be Converted Into Local Currency Charges And Applied To Fob/Plc. Usa Exception: Usa Is Exempt From This Exercise, As E-Inf Has Already Been Incorporated Into Fob/Plc. Euro Countries: All Countries Invoicing Fob/Plc In Euro Should Apply Eur €3 W/M Instead Of Usd. The Uk Remains Excluded From This Euro Application And Should Continue Applying E-Inf In Usd.
A10: CRANE WORLDWIDE | B10: Monthly | C10: Monthly | D10: Bi-Weekly | E10: 46204 | F10: 46234 | G10: 46174 | H10: 46203 | I10: =IFERROR(NETWORKDAYS($A$1,Table1[[#This Row],[FOB/PLC VALIDITY EXPIRY DATE ]]),"-") -> 27 | J10: =IFERROR(NETWORKDAYS($A$1,Table1[[#This Row],[OFR VALIDITY EXPIRY DATE ]]),"-") -> 4 | K10: OFR & Service Update Request | L10: CENTRIC - https://centric.wwalliance.com | M10: Mette Karapetian | N10: Chris Crowder / Helen Li | O10: Monthly | P10: Monthly | Q10: Monthly | R10: Monthly | S10: Bi-Weekly | T10: Bi-Weekly | U10: Bi-Weekly | V10: Monthly | W10: Monthly | X10: Monthly | Y10: Bi-Weekly | Z10: Bi-Weekly | AA10: Bi-Weekly | AB10: Bi-Weekly | AC10: Bi-Weekly | AD10: Quote Separately For Class 3,6,8,9 | AE10: Quote Separately | AF10: Excluded | AG10: Quote Separately | AH10: Quote Separately | AI10: Quote Separately | AJ10: General Cargo FAK, (Non HAZ & HAZ Class 3,6,8,9) | AK10: 1:1 | AL10: Local Currency | AM10: Usd | AN10: Not Allowed | AO10: Yes | AP10: Yes-Increase; No-Decrease | AQ10: 3 | AR10: Yes | AS10: Yes | AT10: -
A11: DACHSER (EXCL. INTRA ASIA) | B11: Yearly | C11: Monthly | D11: Bi-Weekly | E11: 46023 | F11: 46387 | G11: 46174 | H11: 46203 | I11: =IFERROR(NETWORKDAYS($A$1,Table1[[#This Row],[FOB/PLC VALIDITY EXPIRY DATE ]]),"-") -> 136 | J11: =IFERROR(NETWORKDAYS($A$1,Table1[[#This Row],[OFR VALIDITY EXPIRY DATE ]]),"-") -> 4 | K11: OFR & Service Update Request | L11: RFQ TOOL - https://rfqtool.wwalliance.com | M11: Martin Schulz | N11: Nadine | O11: Yearly | P11: Yearly | Q11: Yearly | R11: Yearly | S11: Bi-Weekly | T11: Bi-Weekly | U11: Bi-Weekly | V11: Monthly | W11: Monthly | X11: Monthly | Y11: Bi-Weekly | Z11: Bi-Weekly | AA11: Bi-Weekly | AB11: Bi-Weekly | AC11: Bi-Weekly | AD11: Quote Separately For Class 3,6,8,9 | AE11: Quote Separately | AF11: Excluded | AG11: Quote Separately | AH11: Quote Separately | AI11: Excluded | AJ11: General Cargo FAK, (Non HAZ & HAZ Class 3,6,8,9) | AK11: 1:1 | AL11: Local Currency | AM11: USD/EUR | AN11: Not Allowed | AO11: No | AP11: Yes | AQ11: 3 | AR11: Yes | AS11: Yes | AT11: Rates Are Transfered To Portrix. Hq Have An Issue With Too Many Updates Throughout The Month.
A12: DACHSER (AU/NZ) | B12: Yearly | C12: Quarterly | D12: - | E12: 45809 | F12: 46203 | G12: 46082 | H12: 46203 | I12: =IFERROR(NETWORKDAYS($A$1,Table1[[#This Row],[FOB/PLC VALIDITY EXPIRY DATE ]]),"-") -> 4 | J12: =IFERROR(NETWORKDAYS($A$1,Table1[[#This Row],[OFR VALIDITY EXPIRY DATE ]]),"-") -> 4 | K12: OFR & Service Update Request | L12: CENTRIC - https://centric.wwalliance.com | M12: Jens Pottschul | N12: IRTAsia/Maria Girlie | O12: Yearly | P12: Yearly | Q12: Yearly | R12: Yearly | S12: Bi-Weekly | T12: Bi-Weekly | U12: Bi-Weekly | V12: Quarterly | W12: Quarterly | X12: Na | Y12: Incl. In OFR | Z12: Incl. In OFR | AA12: Incl. In OFR | AB12: Excl. As Per Advisory | AC12: Excl. As Per Advisory | AD12: Quote Separately For Class 3,6,8,9 | AE12: Quote Separately | AF12: Excluded | AG12: Quote Separately | AH12: Quote Separately | AI12: Excluded | AJ12: General Cargo FAK, (Non HAZ & HAZ Class 3,6,8,9) | AK12: 1:1 | AL12: Local Currency | AM12: Usd | AN12: Not Allowed | AO12: Yes | AP12: Yes | AQ12: 5 | AR12: Yes | AS12: Yes | AT12: -
A13: DACHSER INTRA ASIA | B13: Yearly | C13: Yearly | D13: - | E13: 45809 | F13: 46203 | G13: 45809 | H13: 46203 | I13: =IFERROR(NETWORKDAYS($A$1,Table1[[#This Row],[FOB/PLC VALIDITY EXPIRY DATE ]]),"-") -> 4 | J13: =IFERROR(NETWORKDAYS($A$1,Table1[[#This Row],[OFR VALIDITY EXPIRY DATE ]]),"-") -> 4 | K13: OFR & Service Update Request | L13: RFQ TOOL - https://rfqtool.wwalliance.com | M13: Jens Pottschul | N13: IRTAsia/Maria Girlie | O13: Yearly | P13: Yearly | Q13: Yearly | R13: Yearly | S13: Bi-Weekly | T13: Bi-Weekly | U13: Bi-Weekly | V13: Yearly | W13: Yearly | X13: Na | Y13: Incl. In OFR | Z13: Incl. In OFR | AA13: Incl. In OFR | AB13: Bi-Weekly | AC13: Excl. As Per Advisory | AD13: Quote Separately For Class 3,6,8,9 | AE13: Quote Separately | AF13: Excluded | AG13: Quote Separately | AH13: Quote Separately | AI13: Excluded | AJ13: General Cargo FAK, (Non HAZ & HAZ Class 3,6,8,9) | AK13: 1:1 | AL13: Local Currency | AM13: Usd | AN13: Not Allowed | AO13: Yes | AP13: Yes | AQ13: 5 | AR13: Yes | AS13: Yes | AT13: Pre-Defined Fob/Plc
A14: DHL | B14: Yearly | C14: Yearly | D14: Quarterly | E14: 46023 | F14: 46387 | G14: 46113 | H14: 46387 | I14: =IFERROR(NETWORKDAYS($A$1,Table1[[#This Row],[FOB/PLC VALIDITY EXPIRY DATE ]]),"-") -> 136 | J14: =IFERROR(NETWORKDAYS($A$1,Table1[[#This Row],[OFR VALIDITY EXPIRY DATE ]]),"-") -> 136 | K14: OFR & Service Update Request | L14: CENTRIC - https://centric.wwalliance.com | M14: Jakob Bluhme | N14: Santiago | O14: Yearly | P14: Yearly | Q14: Yearly | R14: Yearly | S14: Bi-Weekly | T14: Bi-Weekly | U14: Bi-Weekly | V14: Yearly | W14: Yearly | X14: Yearly | Y14: Quarterly | Z14: Quarterly | AA14: Quarterly | AB14: All US Origins To All Destinations Worldwide USD 6.00 W/M, Intra Asia USD 3.00 W/M, All Other Trade Lanes WW USD 7.00 W/M. | AC14: Excl. As Per Advisory | AD14: Quote Separately For Class 3,6,8,9 | AE14: Excluded | AF14: Excluded | AG14: Excluded | AH14: Excluded | AI14: Excluded | AJ14: General Cargo FAK, (Non HAZ & HAZ Class 3,6,8,9) | AK14: 1:1 | AL14: Local Currency | AM14: USD/EUR | AN14: Not Allowed | AO14: Yes (Except ECRS) | AP14: Yes | AQ14: 5 | AR14: Yes | AS14: Yes | AT14: Pre-Defined Fob/Plc / Ofr Rates Valid For 3 Months. No Updates Locally Nor Updates In Global Tariff Allowed. Only Ems/Ecrs To Change Every Month E-Inf - Updated By Sm For Us Location Only, For Rest Nap
A15: DP WORLD | B15: Yearly | C15: Monthly | D15: Bi-Weekly | E15: 46023 | F15: 46387 | G15: 46174 | H15: 46203 | I15: =IFERROR(NETWORKDAYS($A$1,Table1[[#This Row],[FOB/PLC VALIDITY EXPIRY DATE ]]),"-") -> 136 | J15: =IFERROR(NETWORKDAYS($A$1,Table1[[#This Row],[OFR VALIDITY EXPIRY DATE ]]),"-") -> 4 | K15: OFR & Service Update Request | L15: RFQ TOOL - https://rfqtool.wwalliance.com | M15: Martin Schulz | N15: Nadine/Santiago | O15: Yearly | P15: Yearly | Q15: Yearly | R15: Yearly | S15: Bi-Weekly | T15: Bi-Weekly | U15: Bi-Weekly | V15: Monthly | W15: Monthly | X15: Monthly | Y15: Bi-Weekly | Z15: Bi-Weekly | AA15: Bi-Weekly | AB15: Bi-Weekly | AC15: Bi-Weekly | AD15: Excluded | AE15: Quote Separately | AF15: Excluded | AG15: Quote Separately | AH15: Quote Separately | AI15: Excluded | AJ15: General Cargo FAK, (Non HAZ) | AK15: 1:1 | AL15: Local Currency | AM15: Usd | AN15: Not Allowed | AO15: Yes | AP15: Yes | AQ15: 5 | AR15: Yes | AS15: Yes | AT15: Pre-Defined Fob/Plc
A16: DSV GLOBAL (RFQ & NON-RFQ LANES) | B16: Yearly | C16: Yearly | D16: Monthly | E16: 46113 | F16: 46477 | G16: 46113 | H16: 46477 | I16: =IFERROR(NETWORKDAYS($A$1,Table1[[#This Row],[FOB/PLC VALIDITY EXPIRY DATE ]]),"-") -> 200 | J16: =IFERROR(NETWORKDAYS($A$1,Table1[[#This Row],[OFR VALIDITY EXPIRY DATE ]]),"-") -> 200 | K16: OFR & Service Update Request | L16: CENTRIC - https://centric.wwalliance.com | M16: Jakob Bluhme | N16: Santiago | O16: Yearly | P16: Yearly | Q16: Yearly | R16: Yearly | S16: Bi-Weekly | T16: Bi-Weekly | U16: Bi-Weekly | V16: Monthly | W16: Monthly | X16: Monthly | Y16: Monthly | Z16: Monthly | AA16: Monthly | AB16: Monthly | AC16: Monthly | AD16: Quote Separately For Class 3,6,8,9 | AE16: Quote Separately | AF16: Quote Separately | AG16: Quote Separately | AH16: Quote Separately | AI16: Excluded | AJ16: General Cargo FAK, (Non HAZ & HAZ Class 3,6,8,9) | AO16: No (Except Rate Adjustment On Monthly) | AP16: Yes | AQ16: 20th of Month | AR16: Yes | AS16: Yes
A17: EFL | B17: Yearly | C17: Monthly | D17: Bi-Weekly | E17: 46189 | F17: 46387 | G17: 46189 | H17: 46203 | I17: =IFERROR(NETWORKDAYS($A$1,Table1[[#This Row],[FOB/PLC VALIDITY EXPIRY DATE ]]),"-") -> 136 | J17: =IFERROR(NETWORKDAYS($A$1,Table1[[#This Row],[OFR VALIDITY EXPIRY DATE ]]),"-") -> 4 | K17: OFR & Service Update Request | L17: RFQ TOOL - https://rfqtool.wwalliance.com | M17: Helen Li | N17: - | O17: Yearly | P17: Yearly | Q17: Yearly | R17: Yearly | S17: Bi-Weekly | T17: Bi-Weekly | U17: Bi-Weekly | V17: Monthly | W17: Monthly | X17: Monthly | Y17: Bi-Weekly | Z17: Bi-Weekly | AA17: Bi-Weekly | AB17: Bi-Weekly | AC17: Bi-Weekly | AD17: Excluded | AE17: Excluded | AF17: Excluded | AG17: Excluded | AH17: Excluded | AI17: Excluded | AJ17: General Cargo FAK, (Non HAZ) | AK17: 1:1 | AL17: Usd | AM17: Usd | AN17: Allowed | AO17: No | AP17: No | AQ17: 3 | AR17: Yes | AS17: Yes | AT17: New Rate Card Effective 16Th June
A18: EV CARGO (RA) | B18: Yearly | C18: Quarterly | D18: Bi-Weekly | E18: 46023 | F18: 46387 | G18: 46204 | H18: 46295 | I18: =IFERROR(NETWORKDAYS($A$1,Table1[[#This Row],[FOB/PLC VALIDITY EXPIRY DATE ]]),"-") -> 136 | J18: =IFERROR(NETWORKDAYS($A$1,Table1[[#This Row],[OFR VALIDITY EXPIRY DATE ]]),"-") -> 70 | K18: OFR & Service Update Request | L18: CENTRIC - https://centric.wwalliance.com | M18: Mary-Anne Chua | N18: IRTAsia | O18: Yearly | P18: Yearly | Q18: Yearly | R18: Yearly | S18: Bi-Weekly | T18: Bi-Weekly | U18: Bi-Weekly | V18: Quarterly | W18: Quarterly | X18: Quarterly | Y18: Bi-Weekly | Z18: Bi-Weekly | AA18: Bi-Weekly | AB18: Bi-Weekly | AC18: Bi-Weekly | AD18: Excluded | AE18: Excluded | AF18: Excluded | AG18: Excluded | AH18: Excluded | AI18: Excluded | AJ18: General Cargo FAK, (Non HAZ) | AK18: 1:1 | AL18: Local Currency | AM18: Usd | AN18: Allowed | AO18: Yes | AP18: No | AQ18: 3 | AR18: No | AS18: Yes | AT18: Regional Account
A19: EXPEDITORS | B19: 6 Months | C19: Monthly | D19: Bi-Weekly | E19: 46204 | F19: 46387 | G19: 46174 | H19: 46203 | I19: =IFERROR(NETWORKDAYS($A$1,Table1[[#This Row],[FOB/PLC VALIDITY EXPIRY DATE ]]),"-") -> 136 | J19: =IFERROR(NETWORKDAYS($A$1,Table1[[#This Row],[OFR VALIDITY EXPIRY DATE ]]),"-") -> 4 | K19: OFR & Service Update Request | L19: RFQ TOOL - https://rfqtool.wwalliance.com | M19: Mette Karapetian/Sylvia Lathouwers | N19: - | O19: 6 Months | P19: 6 Months | Q19: 6 Months | R19: 6 Months | S19: Bi-Weekly | T19: Bi-Weekly | U19: Pre-Defined (Agreement) | V19: Monthly | W19: Monthly | X19: Monthly | Y19: Bi-Weekly | Z19: Bi-Weekly | AA19: Bi-Weekly | AB19: Bi-Weekly | AC19: Bi-Weekly | AD19: Quote Separately For Class 3,6,8,9 | AE19: Quote Separately | AF19: Excluded | AG19: Excluded | AH19: Excluded | AI19: Quote Separately | AJ19: General Cargo FAK, (Non HAZ & HAZ Class 3,6,8,9) | AK19: 1 cbm = 1000 kgs except for USA IPI rates | AL19: Local Currency | AM19: USD/EUR | AN19: Not Allowed | AO19: No | AP19: No | AQ19: 3 | AR19: Yes | AS19: Yes | AT19: -
A20: FEDEXTRADE | B20: Yearly | C20: Monthly | D20: Bi-Weekly | E20: 46023 | F20: 46387 | G20: 46174 | H20: 46203 | I20: =IFERROR(NETWORKDAYS($A$1,Table1[[#This Row],[FOB/PLC VALIDITY EXPIRY DATE ]]),"-") -> 136 | J20: =IFERROR(NETWORKDAYS($A$1,Table1[[#This Row],[OFR VALIDITY EXPIRY DATE ]]),"-") -> 4 | K20: OFR & Service Update Request | L20: CENTRIC - https://centric.wwalliance.com | M20: Mette Karapetian/Santiago Milian | N20: Helen | O20: Yearly | P20: Yearly | Q20: Yearly | R20: Yearly | S20: Bi-Weekly | T20: Bi-Weekly | U20: Bi-Weekly | V20: Monthly | W20: Monthly | X20: Monthly | Y20: Bi-Weekly | Z20: Bi-Weekly | AA20: Monthly | AB20: Monthly | AC20: Bi-Weekly | AD20: Excluded | AE20: Excluded | AF20: Excluded | AG20: Excluded | AH20: Excluded | AI20: Excluded | AJ20: General Cargo FAK, (Non HAZ) | AK20: 1 cbm = 1000 kgs | AL20: Local Currency | AM20: USD/EUR | AN20: Not Allowed | AO20: No | AP20: No | AQ20: 3 | AR20: Yes | AS20: Yes | AT20: -
A21: FIBS (RA) | B21: Yearly | C21: Quarterly | D21: Bi-Weekly | E21: 46023 | F21: 46387 | G21: 46204 | H21: 46295 | I21: =IFERROR(NETWORKDAYS($A$1,Table1[[#This Row],[FOB/PLC VALIDITY EXPIRY DATE ]]),"-") -> 136 | J21: =IFERROR(NETWORKDAYS($A$1,Table1[[#This Row],[OFR VALIDITY EXPIRY DATE ]]),"-") -> 70 | K21: OFR & Service Update Request | L21: RFQ TOOL - https://rfqtool.wwalliance.com | M21: Mary-Anne Chua | N21: IRTAsia | O21: Yearly | P21: Yearly | Q21: Yearly | R21: Yearly | S21: Bi-Weekly | T21: Bi-Weekly | U21: Bi-Weekly | V21: Quarterly | W21: Quarterly | X21: Quarterly | Y21: Bi-Weekly | Z21: Bi-Weekly | AA21: Bi-Weekly | AB21: Bi-Weekly | AC21: Bi-Weekly | AD21: Excluded | AE21: Excluded | AF21: Excluded | AG21: Excluded | AH21: Excluded | AI21: Excluded | AJ21: General Cargo FAK, (Non HAZ) | AK21: 1:1 | AL21: Local Currency | AM21: Usd | AN21: Allowed | AO21: No | AP21: No | AQ21: 3 | AR21: Yes | AS21: Yes | AT21: Regional Account
A22: FIVE STAR (RA) | B22: Yearly | C22: Monthly | D22: Bi-Weekly | E22: 46023 | F22: 46387 | G22: 46174 | H22: 46203 | I22: =IFERROR(NETWORKDAYS($A$1,Table1[[#This Row],[FOB/PLC VALIDITY EXPIRY DATE ]]),"-") -> 136 | J22: =IFERROR(NETWORKDAYS($A$1,Table1[[#This Row],[OFR VALIDITY EXPIRY DATE ]]),"-") -> 4 | K22: OFR & Service Update Request | L22: CENTRIC - https://centric.wwalliance.com | M22: Martin Schulz | N22: Dennis Frankowski | O22: Yearly | P22: Yearly | Q22: Yearly | R22: Yearly | S22: Bi-Weekly | T22: Bi-Weekly | U22: Pre-Defined (Agreement) | V22: Monthly | W22: Monthly | X22: Quarterly | Y22: Bi-Weekly | Z22: Bi-Weekly | AA22: Bi-Weekly | AB22: Bi-Weekly | AC22: Bi-Weekly | AD22: Excluded | AE22: Excluded | AF22: Excluded | AG22: Excluded | AH22: Excluded | AI22: Excluded | AJ22: General Cargo FAK, (Non HAZ) | AK22: 1:1 | AL22: Local Currency | AM22: USD/EUR | AN22: Not Allowed | AO22: No | AP22: No | AQ22: 3 | AR22: Yes | AS22: Yes | AT22: Regional Account
A23: FLEXPORT | B23: Yearly | C23: Monthly | D23: Bi-Weekly | E23: 46023 | F23: 46387 | G23: 46174 | H23: 46203 | I23: =IFERROR(NETWORKDAYS($A$1,Table1[[#This Row],[FOB/PLC VALIDITY EXPIRY DATE ]]),"-") -> 136 | J23: =IFERROR(NETWORKDAYS($A$1,Table1[[#This Row],[OFR VALIDITY EXPIRY DATE ]]),"-") -> 4 | K23: OFR & Service Update Request | L23: RFQ TOOL - https://rfqtool.wwalliance.com | M23: Jens Pottschul | N23: Michelle Yu Cc. Maria Girlie & Irt Asia | O23: Yearly | P23: Yearly | Q23: Yearly | R23: Yearly | S23: Bi-Weekly | T23: Bi-Weekly | U23: Bi-Weekly | V23: Monthly | W23: Monthly | X23: Quarterly | Y23: Bi-Weekly | Z23: Bi-Weekly | AA23: Bi-Weekly | AB23: Bi-Weekly | AC23: Bi-Weekly | AD23: Excluded | AE23: Quote Separately | AF23: Excluded | AG23: Excluded | AH23: Excluded | AI23: Excluded | AJ23: General Cargo FAK, (Non HAZ) | AK23: 1:1000 | AL23: Local Currency | AM23: Usd | AN23: Not Allowed | AO23: No | AP23: No | AQ23: 3 | AR23: Yes | AS23: Yes | AT23: As Flexport Pull Our Rates Via Api We Can Reduce Only Locally As Long As Grdb Is Maintained So When Flexport Pull Api It Will Reflect Here As Well.
A24: GEBR. WEISS | B24: Yearly | C24: Monthly | D24: Bi-Weekly | E24: 46023 | F24: 46387 | G24: 46174 | H24: 46203 | I24: =IFERROR(NETWORKDAYS($A$1,Table1[[#This Row],[FOB/PLC VALIDITY EXPIRY DATE ]]),"-") -> 136 | J24: =IFERROR(NETWORKDAYS($A$1,Table1[[#This Row],[OFR VALIDITY EXPIRY DATE ]]),"-") -> 4 | K24: OFR & Service Update Request | L24: CENTRIC - https://centric.wwalliance.com | M24: Jakob Bluhme | N24: Santiago | O24: Yearly | P24: Yearly | Q24: Yearly | R24: Yearly | S24: Bi-Weekly | T24: Bi-Weekly | U24: Bi-Weekly | V24: Monthly | W24: Monthly | X24: Monthly | Y24: Bi-Weekly | Z24: Bi-Weekly | AA24: Bi-Weekly | AB24: Bi-Weekly | AC24: Bi-Weekly | AD24: Quote Separately For Class 3,6,8,9 | AE24: Quote Separately | AF24: Excluded | AG24: Quote Separately | AH24: Quote Separately | AI24: Excluded | AJ24: General Cargo FAK, (Non HAZ & HAZ Class 3,6,8,9) | AK24: 0.04375 | AL24: Local Currency | AM24: Usd | AN24: Not Allowed | AO24: Yes | AP24: No | AQ24: 3 | AR24: Yes | AS24: Yes | AT24: -
A25: GEODIS | B25: Yearly | C25: Bi-Weekly | D25: Bi-Weekly | E25: 46023 | F25: 46387 | G25: 46174 | H25: 46203 | I25: =IFERROR(NETWORKDAYS($A$1,Table1[[#This Row],[FOB/PLC VALIDITY EXPIRY DATE ]]),"-") -> 136 | J25: =IFERROR(NETWORKDAYS($A$1,Table1[[#This Row],[OFR VALIDITY EXPIRY DATE ]]),"-") -> 4 | K25: OFR & Service Update Request | L25: RFQ TOOL - https://rfqtool.wwalliance.com | M25: Martin Schulz/Susanne Elsborg-Jensen | N25: Susanne | O25: Yearly | P25: Yearly | Q25: Yearly | R25: Yearly | S25: Bi-Weekly | T25: Bi-Weekly | U25: Bi-Weekly | V25: Bi-Weekly | W25: Bi-Weekly | X25: Bi-Weekly | Y25: Bi-Weekly | Z25: Bi-Weekly | AA25: Bi-Weekly | AB25: Bi-Weekly | AC25: Bi-Weekly | AD25: Excluded | AE25: Quote Separately | AF25: Excluded | AG25: Excluded | AH25: Excluded | AI25: Excluded | AJ25: General Cargo FAK, (Non HAZ) | AK25: 1:1 | AL25: Local Currency | AM25: USD/EUR | AN25: Not Allowed | AO25: Yes | AP25: Yes | AQ25: 3 | AR25: Yes | AS25: Yes | AT25: Monthly Ofr Rates - Can Be Reduced But Needs To Be Displayed In The Grdb.
A26: HELLMANN | B26: Yearly | C26: Quarterly | D26: Bi-Weekly | E26: 46054 | F26: 46387 | G26: 46143 | H26: 46265 | I26: =IFERROR(NETWORKDAYS($A$1,Table1[[#This Row],[FOB/PLC VALIDITY EXPIRY DATE ]]),"-") -> 136 | J26: =IFERROR(NETWORKDAYS($A$1,Table1[[#This Row],[OFR VALIDITY EXPIRY DATE ]]),"-") -> 48 | K26: OFR & Service Update Request | L26: CENTRIC - https://centric.wwalliance.com | M26: Martin Schulz/Nadine Beer | N26: Nadine | O26: Yearly | P26: Yearly | Q26: Yearly | R26: Yearly | S26: Bi-Weekly | T26: Bi-Weekly | U26: Bi-Weekly | V26: Quarterly | W26: Quarterly | X26: Quarterly | Y26: Bi-Weekly | Z26: Bi-Weekly | AA26: Bi-Weekly | AB26: Pre-Defined (Agreement) | AC26: Pre-Defined (Agreement) | AD26: Quote Separately For Class 2,4,5,6 And 3,8,9 | AE26: Quote Separately | AF26: Quote Separately | AG26: Excluded | AH26: Excluded | AI26: Excluded | AJ26: General Cargo FAK, (Non HAZ & HAZ Class 2,4,5,6 & 3,8,9) | AK26: 1:3 | AL26: Local Currency | AM26: USD/EUR | AN26: Not Allowed | AO26: No | AP26: Yes | AQ26: 22nd of Month | AR26: Yes | AS26: Yes | AT26: Hellmann Does Not Accept Any Interim Updates.
A27: HELLMANN INTRA ASIA | B27: Yearly | C27: Quarterly | D27: Bi-Weekly | E27: 46023 | F27: 46387 | G27: 46204 | H27: 46295 | I27: =IFERROR(NETWORKDAYS($A$1,Table1[[#This Row],[FOB/PLC VALIDITY EXPIRY DATE ]]),"-") -> 136 | J27: =IFERROR(NETWORKDAYS($A$1,Table1[[#This Row],[OFR VALIDITY EXPIRY DATE ]]),"-") -> 70 | K27: OFR & Service Update Request | L27: RFQ TOOL - https://rfqtool.wwalliance.com | M27: Jens Pottschul | N27: IRTAsia | O27: Yearly | P27: Yearly | Q27: Yearly | R27: Yearly | S27: Bi-Weekly | T27: Bi-Weekly | U27: Bi-Weekly | V27: Quarterly | W27: Quarterly | X27: Na | Y27: Bi-Weekly | Z27: Bi-Weekly | AA27: Bi-Weekly | AB27: Bi-Weekly | AC27: Excl. As Per Advisory | AD27: Quote Separately For Class 2,4,5,6 And 3,8,9 | AE27: Quote Separately | AF27: Quote Separately | AG27: Excluded | AH27: Excluded | AI27: Excluded | AJ27: General Cargo FAK, (Non HAZ & HAZ Class 2,4,5,6 & 3,8,9) | AK27: 1:1 | AL27: Local Currency | AM27: Usd | AN27: Not Allowed | AO27: No | AP27: Yes | AQ27: 5 | AR27: Yes | AS27: Yes | AT27: Pre-Defined Fob/Plc
A28: JAS OCEAN | B28: Yearly | C28: Monthly | D28: Bi-Weekly | E28: 46023 | F28: 46387 | G28: 46174 | H28: 46203 | I28: =IFERROR(NETWORKDAYS($A$1,Table1[[#This Row],[FOB/PLC VALIDITY EXPIRY DATE ]]),"-") -> 136 | J28: =IFERROR(NETWORKDAYS($A$1,Table1[[#This Row],[OFR VALIDITY EXPIRY DATE ]]),"-") -> 4 | K28: OFR & Service Update Request | L28: CENTRIC - https://centric.wwalliance.com | M28: Chris Crowder | N28: Helen | O28: Yearly | P28: Yearly | Q28: Yearly | R28: Yearly | S28: Bi-Weekly | T28: Bi-Weekly | U28: Bi-Weekly | V28: Monthly | W28: Monthly | X28: Monthly | Y28: Bi-Weekly | Z28: Bi-Weekly | AA28: Bi-Weekly | AB28: Bi-Weekly | AC28: Bi-Weekly | AD28: Excluded | AE28: Excluded | AF28: Excluded | AG28: Excluded | AH28: Excluded | AI28: Quote Separately | AJ28: General Cargo FAK, (Non HAZ) | AK28: 1 cbm = 1000 kgs | AL28: Local Currency | AM28: USD/EUR | AN28: Not Allowed | AO28: Yes | AP28: No | AQ28: 2 | AR28: Yes | AS28: Yes | AT28: Any Reductions Must Be Shared, Filed, And Ensure Grdb Updated
A29: KLN | B29: Quarterly | C29: Monthly | D29: Bi-Weekly | E29: 46204 | F29: 46295 | G29: 46174 | H29: 46203 | I29: =IFERROR(NETWORKDAYS($A$1,Table1[[#This Row],[FOB/PLC VALIDITY EXPIRY DATE ]]),"-") -> 70 | J29: =IFERROR(NETWORKDAYS($A$1,Table1[[#This Row],[OFR VALIDITY EXPIRY DATE ]]),"-") -> 4 | K29: OFR & Service Update Request | L29: RFQ TOOL - https://rfqtool.wwalliance.com | M29: Jens Pottschul | N29: IRTAsia | O29: Quarterly | P29: Quarterly | Q29: Quarterly | R29: Quarterly | S29: Bi-Weekly | T29: Bi-Weekly | U29: Bi-Weekly | V29: Monthly | W29: Monthly | X29: Quarterly | Y29: Bi-Weekly | Z29: Bi-Weekly | AA29: Bi-Weekly | AB29: Bi-Weekly | AC29: Bi-Weekly | AD29: Excluded | AE29: Excluded | AF29: Excluded | AG29: Excluded | AH29: Excluded | AI29: Excluded | AJ29: General Cargo FAK, (Non HAZ) | AK29: 1:1000 | AL29: Local Currency | AM29: Usd | AN29: Not Allowed | AO29: No | AP29: No | AQ29: 3 | AR29: Yes | AS29: Yes | AT29: As Per March 1St 2026, Ofr Validity Will Become Monthly.
A30: KINTETSU | B30: 6 Months | C30: Monthly | D30: Bi-Weekly | E30: 46204 | F30: 46387 | G30: 46174 | H30: 46203 | I30: =IFERROR(NETWORKDAYS($A$1,Table1[[#This Row],[FOB/PLC VALIDITY EXPIRY DATE ]]),"-") -> 136 | J30: =IFERROR(NETWORKDAYS($A$1,Table1[[#This Row],[OFR VALIDITY EXPIRY DATE ]]),"-") -> 4 | K30: OFR & Service Update Request | L30: CENTRIC - https://centric.wwalliance.com | M30: Jens Pottschul/Michelle Yu | N30: IRTAsia | O30: 6 Months | P30: 6 Months | Q30: 6 Months | R30: 6 Months | S30: Bi-Weekly | T30: Bi-Weekly | U30: Bi-Weekly | W30: Monthly | X30: Monthly | Y30: Bi-Weekly | Z30: Bi-Weekly | AA30: Bi-Weekly | AB30: Bi-Weekly | AC30: Bi-Weekly | AD30: Excluded | AE30: Excluded | AF30: Excluded | AG30: Excluded | AH30: Excluded | AI30: Excluded | AJ30: General Cargo FAK, (Non HAZ) | AK30: 1:1 | AL30: Local Currency | AM30: Usd | AN30: Not Allowed | AO30: Yes | AP30: No | AQ30: 3 | AR30: No | AS30: No | AT30: Kwe Are Happy For Local Negotiaitons As Long As This Is Updated In The Next Viable Update. I.E In The Bi-Weekly Tariff Update. Would Also Like An Overview Of The Changes Made To Any Fob/Ofr/Plc Charges Which Are Reductions So They Are Able To Inform And Align With Local Offices.
A31: KUEHNE & NAGEL | B31: Yearly | C31: Monthly | D31: Monthly | E31: 46023 | F31: 46387 | G31: 46174 | H31: 46203 | I31: =IFERROR(NETWORKDAYS($A$1,Table1[[#This Row],[FOB/PLC VALIDITY EXPIRY DATE ]]),"-") -> 136 | J31: =IFERROR(NETWORKDAYS($A$1,Table1[[#This Row],[OFR VALIDITY EXPIRY DATE ]]),"-") -> 4 | K31: OFR & Service Update Request | L31: RFQ TOOL - https://rfqtool.wwalliance.com | M31: Martin Schulz/Nadine Beer | N31: Nadine | O31: Yearly | P31: Yearly | Q31: Yearly | R31: Yearly | S31: Bi-Weekly | T31: Bi-Weekly | U31: Bi-Weekly | V31: Monthly | W31: Monthly | X31: Incl. In OFR | Y31: Monthly | Z31: Monthly | AA31: Monthly | AB31: Monthly | AC31: Monthly | AD31: Excluded | AE31: Quote Separately | AF31: Excluded | AG31: Excluded | AH31: Excluded | AI31: Excluded | AJ31: General Cargo FAK, (Non HAZ) | AK31: 0.04375 | AL31: Local Currency | AM31: Usd | AN31: Not Allowed | AO31: Yes (Except EDS/ESF) | AP31: Yes | AQ31: 13th of Month | AR31: Yes | AS31: Yes | AT31: Pre-Defined Fob/Plc (Partial) / K&N Does Not Accept Any Interim Updates.
